<?xml version="1.0" encoding="utf-8"?>
<!-- This URDF was automatically created by SolidWorks to URDF Exporter! Originally created by Stephen Brawner (brawner@gmail.com) 
     Commit Version: 1.6.0-4-g7f85cfe  Build Version: 1.6.7995.38578
     For more information, please see http://wiki.ros.org/sw_urdf_exporter -->
<robot
  name="Quadruped">
  <link
    name="base_link">
    <inertial>
      <origin
        xyz="0.00952304124015213 -0.0384999999836778 0.0139434635699888"
        rpy="0 0 0" />
      <mass
        value="0.267600954992518" />
      <inertia
        ixx="9.27694563083199E-05"
        ixy="7.75151444361343E-14"
        ixz="-2.56413813792822E-17"
        iyy="3.60005886849802E-05"
        iyz="6.50891916828143E-13"
        izz="9.02125920436437E-05" />
    </inertial>
    <visual>
      <origin
        xyz="0 0 0"
        rpy="0 0 0" />
      <geometry>
        <mesh
          filename="meshes/base_link.STL" />
      </geometry>
      <material
        name="">
        <color
          rgba="0.894117647058823 0.913725490196078 0.929411764705882 1" />
      </material>
    </visual>
    <collision>
      <origin
        xyz="0 0 0"
        rpy="0 0 0" />
      <geometry>
        <mesh
          filename="meshes/base_link.STL" />
      </geometry>
    </collision>
  </link>
  <link
    name="leg_1_hip">
    <inertial>
      <origin
        xyz="0.0238940041079062 0.031792584261488 0.026781309985059"
        rpy="0 0 0" />
      <mass
        value="0.067077762894934" />
      <inertia
        ixx="2.37941932882446E-05"
        ixy="-1.03091198376917E-06"
        ixz="-2.0851787492699E-08"
        iyy="2.49239414009393E-05"
        iyz="-5.27852080190577E-11"
        izz="1.06832163798715E-05" />
    </inertial>
    <visual>
      <origin
        xyz="0 0 0"
        rpy="0 0 0" />
      <geometry>
        <mesh
          filename="meshes/leg_1_hip.STL" />
      </geometry>
      <material
        name="">
        <color
          rgba="0.894117647058823 0.913725490196078 0.929411764705882 1" />
      </material>
    </visual>
    <collision>
      <origin
        xyz="0 0 0"
        rpy="0 0 0" />
      <geometry>
        <mesh
          filename="meshes/leg_1_hip.STL" />
      </geometry>
    </collision>
  </link>
  <joint
    name="leg1_hip_joint"
    type="revolute">
    <origin
      xyz="0.06197 -0.082557 0.0385"
      rpy="3.1416 0 -0.056054" />
    <parent
      link="base_link" />
    <child
      link="leg_1_hip" />
    <axis
      xyz="0 0 1" />
    <limit
      lower="0"
      upper="3"
      effort="10"
      velocity="5" />
  </joint>
  <link
    name="leg_1_knee">
    <inertial>
      <origin
        xyz="-0.0416421850295465 0.0235364816921849 -0.0309446231834363"
        rpy="0 0 0" />
      <mass
        value="0.0696914928060746" />
      <inertia
        ixx="2.57631280608198E-05"
        ixy="-3.96590049532033E-07"
        ixz="-1.13787464895981E-07"
        iyy="1.97651580535786E-05"
        iyz="-3.60662001602266E-07"
        izz="2.57670138527122E-05" />
    </inertial>
    <visual>
      <origin
        xyz="0 0 0"
        rpy="0 0 0" />
      <geometry>
        <mesh
          filename="meshes/leg_1_knee.STL" />
      </geometry>
      <material
        name="">
        <color
          rgba="0.298039215686275 0.298039215686275 0.298039215686275 1" />
      </material>
    </visual>
    <collision>
      <origin
        xyz="0 0 0"
        rpy="0 0 0" />
      <geometry>
        <mesh
          filename="meshes/leg_1_knee.STL" />
      </geometry>
    </collision>
  </link>
  <joint
    name="leg_1_knee_joint"
    type="revolute">
    <origin
      xyz="0.060665 0.04177 0.036307"
      rpy="3.1416 0 -1.5708" />
    <parent
      link="leg_1_hip" />
    <child
      link="leg_1_knee" />
    <axis
      xyz="0 -1 0" />
    <limit
      lower="0"
      upper="3"
      effort="10"
      velocity="5" />
  </joint>
  <link
    name="leg_1_ankle">
    <inertial>
      <origin
        xyz="3.36841665671272E-13 0.0280775387533091 0.0172277429088525"
        rpy="0 0 0" />
      <mass
        value="0.0169824099129692" />
      <inertia
        ixx="1.11378366738052E-05"
        ixy="-3.17637355220363E-22"
        ixz="-4.87043944671223E-21"
        iyy="3.39360074925846E-06"
        iyz="-1.38701645112892E-20"
        izz="9.36668224662848E-06" />
    </inertial>
    <visual>
      <origin
        xyz="0 0 0"
        rpy="0 0 0" />
      <geometry>
        <mesh
          filename="meshes/leg_1_ankle.STL" />
      </geometry>
      <material
        name="">
        <color
          rgba="0.298039215686275 0.298039215686275 0.298039215686275 1" />
      </material>
    </visual>
    <collision>
      <origin
        xyz="0 0 0"
        rpy="0 0 0" />
      <geometry>
        <mesh
          filename="meshes/leg_1_ankle.STL" />
      </geometry>
    </collision>
  </link>
  <joint
    name="leg_1_ankle_joint"
    type="revolute">
    <origin
      xyz="-0.046499 0.0005 -0.045091"
      rpy="3.1416 -1.0269 -3.1416" />
    <parent
      link="leg_1_knee" />
    <child
      link="leg_1_ankle" />
    <axis
      xyz="0 -1 0" />
    <limit
      lower="0"
      upper="3"
      effort="10"
      velocity="5" />
  </joint>
  <link
    name="leg_2_hip">
    <inertial>
      <origin
        xyz="0.0238940050809038 -0.0318845074159718 0.0267811755415515"
        rpy="0 0 0" />
      <mass
        value="0.0670777528778422" />
      <inertia
        ixx="2.37941887246457E-05"
        ixy="1.03091155379707E-06"
        ixz="-2.08140379608125E-08"
        iyy="2.49239360302726E-05"
        iyz="-5.3739351215238E-11"
        izz="1.06832159298643E-05" />
    </inertial>
    <visual>
      <origin
        xyz="0 0 0"
        rpy="0 0 0" />
      <geometry>
        <mesh
          filename="meshes/leg_2_hip.STL" />
      </geometry>
      <material
        name="">
        <color
          rgba="0.894117647058823 0.913725490196078 0.929411764705882 1" />
      </material>
    </visual>
    <collision>
      <origin
        xyz="0 0 0"
        rpy="0 0 0" />
      <geometry>
        <mesh
          filename="meshes/leg_2_hip.STL" />
      </geometry>
    </collision>
  </link>
  <joint
    name="leg_2_hip_joint"
    type="revolute">
    <origin
      xyz="0.06177 0.0055571 0.0385"
      rpy="3.1416 0 0.90705" />
    <parent
      link="base_link" />
    <child
      link="leg_2_hip" />
    <axis
      xyz="0 0 -1" />
    <limit
      lower="0"
      upper="3"
      effort="10"
      velocity="5" />
  </joint>
  <link
    name="leg_2_knee">
    <inertial>
      <origin
        xyz="-0.0172246793386854 0.0235364817623663 0.0489382442054168"
        rpy="0 0 0" />
      <mass
        value="0.0696914931210657" />
      <inertia
        ixx="2.58698344231019E-05"
        ixy="-1.27169967368347E-07"
        ixz="4.44517106603271E-08"
        iyy="1.97651573719921E-05"
        iyz="5.20757570984245E-07"
        izz="2.56603065089136E-05" />
    </inertial>
    <visual>
      <origin
        xyz="0 0 0"
        rpy="0 0 0" />
      <geometry>
        <mesh
          filename="meshes/leg_2_knee.STL" />
      </geometry>
      <material
        name="">
        <color
          rgba="0.894117647058823 0.913725490196078 0.929411764705882 1" />
      </material>
    </visual>
    <collision>
      <origin
        xyz="0 0 0"
        rpy="0 0 0" />
      <geometry>
        <mesh
          filename="meshes/leg_2_knee.STL" />
      </geometry>
    </collision>
  </link>
  <joint
    name="leg_2_knee_joint"
    type="revolute">
    <origin
      xyz="0.060665 -0.04197 0.036307"
      rpy="0 0 1.5708" />
    <parent
      link="leg_2_hip" />
    <child
      link="leg_2_knee" />
    <axis
      xyz="0 -1 0" />
    <limit
      lower="0"
      upper="3"
      effort="10"
      velocity="5" />
  </joint>
  <link
    name="leg_2_ankle">
    <inertial>
      <origin
        xyz="-8.41826608422025E-14 0.0280775387534135 0.0172277429085822"
        rpy="0 0 0" />
      <mass
        value="0.0169824099129692" />
      <inertia
        ixx="1.11378366738051E-05"
        ixy="-3.42121901351932E-21"
        ixz="6.85567291683949E-21"
        iyy="3.39360074925846E-06"
        iyz="9.15854374218712E-21"
        izz="9.36668224662836E-06" />
    </inertial>
    <visual>
      <origin
        xyz="0 0 0"
        rpy="0 0 0" />
      <geometry>
        <mesh
          filename="meshes/leg_2_ankle.STL" />
      </geometry>
      <material
        name="">
        <color
          rgba="0.894117647058823 0.913725490196078 0.929411764705882 1" />
      </material>
    </visual>
    <collision>
      <origin
        xyz="0 0 0"
        rpy="0 0 0" />
      <geometry>
        <mesh
          filename="meshes/leg_2_ankle.STL" />
      </geometry>
    </collision>
  </link>
  <joint
    name="leg_2_ankle_joint"
    type="revolute">
    <origin
      xyz="-0.013342 0.0005 0.063382"
      rpy="0 1.0652 0" />
    <parent
      link="leg_2_knee" />
    <child
      link="leg_2_ankle" />
    <axis
      xyz="0 -1 0" />
    <limit
      lower="0"
      upper="3"
      effort="10"
      velocity="5" />
  </joint>
  <link
    name="leg_3_hip">
    <inertial>
      <origin
        xyz="0.0241828875435537 0.0321769622766387 0.0275025602046744"
        rpy="0 0 0" />
      <mass
        value="0.0662764719650818" />
      <inertia
        ixx="2.3772765111836E-05"
        ixy="-1.03091231788725E-06"
        ixz="-2.08511149937911E-08"
        iyy="2.49025134599967E-05"
        iyz="-5.21654116313531E-11"
        izz="1.06429146618344E-05" />
    </inertial>
    <visual>
      <origin
        xyz="0 0 0"
        rpy="0 0 0" />
      <geometry>
        <mesh
          filename="meshes/leg_3_hip.STL" />
      </geometry>
      <material
        name="">
        <color
          rgba="0.894117647058823 0.913725490196078 0.929411764705882 1" />
      </material>
    </visual>
    <collision>
      <origin
        xyz="0 0 0"
        rpy="0 0 0" />
      <geometry>
        <mesh
          filename="meshes/leg_3_hip.STL" />
      </geometry>
    </collision>
  </link>
  <joint
    name="leg_3_hip_joint"
    type="revolute">
    <origin
      xyz="-0.04277 0.0055571 0.0395"
      rpy="-3.1416 0 -2.9812" />
    <parent
      link="base_link" />
    <child
      link="leg_3_hip" />
    <axis
      xyz="0 0 1" />
    <limit
      lower="0"
      upper="3"
      effort="10"
      velocity="5" />
  </joint>
  <link
    name="leg_3_knee">
    <inertial>
      <origin
        xyz="0.022535757284239 0.0235364816495744 0.0467309416989118"
        rpy="0 0 0" />
      <mass
        value="0.0696914925297254" />
      <inertia
        ixx="2.58574870571026E-05"
        ixy="1.84030699074035E-07"
        ixz="-6.64124283965437E-08"
        iyy="1.97651572319704E-05"
        iyz="5.03481342492272E-07"
        izz="2.56726536984704E-05" />
    </inertial>
    <visual>
      <origin
        xyz="0 0 0"
        rpy="0 0 0" />
      <geometry>
        <mesh
          filename="meshes/leg_3_knee.STL" />
      </geometry>
      <material
        name="">
        <color
          rgba="0.298039215686275 0.298039215686275 0.298039215686275 1" />
      </material>
    </visual>
    <collision>
      <origin
        xyz="0 0 0"
        rpy="0 0 0" />
      <geometry>
        <mesh
          filename="meshes/leg_3_knee.STL" />
      </geometry>
    </collision>
  </link>
  <joint
    name="leg_3_knee_joint"
    type="revolute">
    <origin
      xyz="0.060665 0.04177 0.037307"
      rpy="0 0 1.5708" />
    <parent
      link="leg_3_hip" />
    <child
      link="leg_3_knee" />
    <axis
      xyz="0 1 0" />
    <limit
      lower="0"
      upper="3"
      effort="10"
      velocity="5" />
  </joint>
  <link
    name="leg_3_ankle">
    <inertial>
      <origin
        xyz="5.43953770915095E-13 -0.0280775387471619 -0.0172277429114426"
        rpy="0 0 0" />
      <mass
        value="0.0169824099129693" />
      <inertia
        ixx="1.11378366738053E-05"
        ixy="-6.35274710440725E-22"
        ixz="3.17637355220363E-21"
        iyy="3.3936007492585E-06"
        iyz="-2.27640104574593E-20"
        izz="9.3666822466285E-06" />
    </inertial>
    <visual>
      <origin
        xyz="0 0 0"
        rpy="0 0 0" />
      <geometry>
        <mesh
          filename="meshes/leg_3_ankle.STL" />
      </geometry>
      <material
        name="">
        <color
          rgba="0.894117647058823 0.913725490196078 0.929411764705882 1" />
      </material>
    </visual>
    <collision>
      <origin
        xyz="0 0 0"
        rpy="0 0 0" />
      <geometry>
        <mesh
          filename="meshes/leg_3_ankle.STL" />
      </geometry>
    </collision>
  </link>
  <joint
    name="leg_3_ankle"
    type="revolute">
    <origin
      xyz="0.020276 0.0005 0.061516"
      rpy="-3.1416 -0.27473 0" />
    <parent
      link="leg_3_knee" />
    <child
      link="leg_3_ankle" />
    <axis
      xyz="0 -1 0" />
    <limit
      lower="0"
      upper="3"
      effort="10"
      velocity="5" />
  </joint>
  <link
    name="leg_4_hip">
    <inertial>
      <origin
        xyz="0.0241828890191002 -0.0321769654646224 0.0265024258626731"
        rpy="0 0 0" />
      <mass
        value="0.0662764580966196" />
      <inertia
        ixx="2.37727593793705E-05"
        ixy="1.03091197436808E-06"
        ixz="-2.08148141525333E-08"
        iyy="2.49025066568201E-05"
        iyz="-5.32912244693011E-11"
        izz="1.06429147248075E-05" />
    </inertial>
    <visual>
      <origin
        xyz="0 0 0"
        rpy="0 0 0" />
      <geometry>
        <mesh
          filename="meshes/leg_4_hip.STL" />
      </geometry>
      <material
        name="">
        <color
          rgba="0.298039215686275 0.298039215686275 0.298039215686275 1" />
      </material>
    </visual>
    <collision>
      <origin
        xyz="0 0 0"
        rpy="0 0 0" />
      <geometry>
        <mesh
          filename="meshes/leg_4_hip.STL" />
      </geometry>
    </collision>
  </link>
  <joint
    name="leg_4_hip_joint"
    type="revolute">
    <origin
      xyz="-0.04277 -0.082557 0.0385"
      rpy="-3.1416 0 2.7813" />
    <parent
      link="base_link" />
    <child
      link="leg_4_hip" />
    <axis
      xyz="0 0 -1" />
    <limit
      lower="0"
      upper="3"
      effort="10"
      velocity="5" />
  </joint>
  <link
    name="leg_4_knee">
    <inertial>
      <origin
        xyz="0.00942340047874446 -0.0235364817845292 0.0510180443538506"
        rpy="0 0 0" />
      <mass
        value="0.0696914932488991" />
      <inertia
        ixx="2.58784171248653E-05"
        ixy="-4.48351221784355E-08"
        ixz="-1.0197338788005E-08"
        iyy="1.97651575974079E-05"
        iyz="-5.34182043984853E-07"
        izz="2.56517241069841E-05" />
    </inertial>
    <visual>
      <origin
        xyz="0 0 0"
        rpy="0 0 0" />
      <geometry>
        <mesh
          filename="meshes/leg_4_knee.STL" />
      </geometry>
      <material
        name="">
        <color
          rgba="0.894117647058823 0.913725490196078 0.929411764705882 1" />
      </material>
    </visual>
    <collision>
      <origin
        xyz="0 0 0"
        rpy="0 0 0" />
      <geometry>
        <mesh
          filename="meshes/leg_4_knee.STL" />
      </geometry>
    </collision>
  </link>
  <joint
    name="leg_4_knee_joint"
    type="revolute">
    <origin
      xyz="0.060665 -0.04177 0.036307"
      rpy="0 0 -1.5708" />
    <parent
      link="leg_4_hip" />
    <child
      link="leg_4_knee" />
    <axis
      xyz="0 -1 0" />
    <limit
      lower="0"
      upper="3"
      effort="10"
      velocity="5" />
  </joint>
  <link
    name="leg_4_ankle">
    <inertial>
      <origin
        xyz="-4.28879154412698E-13 -0.0280775387534245 -0.017227742908787"
        rpy="0 0 0" />
      <mass
        value="0.0169824099129693" />
      <inertia
        ixx="1.11378366738053E-05"
        ixy="1.28643128864247E-20"
        ixz="-5.39983503874616E-21"
        iyy="3.39360074925848E-06"
        iyz="-3.28225267061041E-21"
        izz="9.36668224662849E-06" />
    </inertial>
    <visual>
      <origin
        xyz="0 0 0"
        rpy="0 0 0" />
      <geometry>
        <mesh
          filename="meshes/leg_4_ankle.STL" />
      </geometry>
      <material
        name="">
        <color
          rgba="0.894117647058823 0.913725490196078 0.929411764705882 1" />
      </material>
    </visual>
    <collision>
      <origin
        xyz="0 0 0"
        rpy="0 0 0" />
      <geometry>
        <mesh
          filename="meshes/leg_4_ankle.STL" />
      </geometry>
    </collision>
  </link>
  <joint
    name="leg_4_ankle_joint"
    type="revolute">
    <origin
      xyz="0.0033472 -0.0005 0.064685"
      rpy="-3.1416 -0.5198 3.1416" />
    <parent
      link="leg_4_knee" />
    <child
      link="leg_4_ankle" />
    <axis
      xyz="0 -1 0" />
    <limit
      lower="0"
      upper="3"
      effort="10"
      velocity="5" />
  </joint>
</robot>